Workbook

Sheet README
B1: MODEL PORTFOLIO - MASTER WORKBOOK
B3: HOW THIS WORKBOOK IS ORGANISED
B4: Blue text = you type it. Black = formula. Green = link from another sheet. Never overwrite black/green cells.
B5: settings - inception date, starting capital, benchmark (inputs).
B6: securities - master list of stocks: ticker, sector, TARGET weight (inputs).
B7: transactions - every buy/sell ever made. APPEND ONLY - never edit or delete an old row; add a correcting row instead.
B8: prices - one row per update date: closing price of every stock + Nifty 500 level (inputs).
B9: changes - public disclosure log: what changed and WHY (inputs). Shown on the website.
B10: positions / nav / calc - all calculations (formulas). Do not type here.
B11: theses - your sector write-ups copied from the original file (text).
B13: UPDATE ROUTINE (every 1st and 16th, or after any trade)
B14: 1. prices: add ONE new row at the bottom: date + closing price of every stock + Nifty 500 close. Do not edit older rows.
... B27: H. Returns are price returns (no dividends, costs or taxes). Rebalances should be self-funded; any cash is tracked in the cash line.

Sheet settings
A1: SETTINGS (inputs)
A2: Inception date | B2: 46101 | C2: Assumption A - confirm
A3: Starting capital (Rs) | B3: 10000000 | C3: Assumption C - confirm
A4: Benchmark name | B4: Nifty 500 | C4: Shown on website
A5: Currency | B5: INR

Sheet securities
A1: ticker | B1: company | C1: sector | D1: industry | E1: target_weight | F1: yahoo_symbol (for later) | G1: verify_ticker | H1: note
A2: KOTAKBANK | B2: Kotak Mahindra Bank | C2: Financial Services | D2: Bank - Pvt | E2: 0.05 | F2: KOTAKBANK.NS | G2: 0
A3: HDFCBANK | B3: HDFC Bank | C3: Financial Services | D3: Bank - Pvt | E3: 0.08 | F3: HDFCBANK.NS | G3: 0
A4: SBIN | B4: SBI | C4: Financial Services | D4: Bank - PSU | E4: 0.07 | F4: SBIN.NS | G4: 0
A5: MANAPPURAM | B5: Manappuram Finance | C5: Financial Services | D5: NBFC - Gold & MFI | E5: 0.05 | F5: MANAPPURAM.NS | G5: 0
A6: SHRIRAMFIN | B6: Shriram Finance | C6: Financial Services | D6: NBFC - Auto | E6: 0.05 | F6: SHRIRAMFIN.NS | G6: 0
A7: RECLTD | B7: REC Ltd | C7: Financial Services | D7: NBFC - Power | E7: 0.04 | F7: RECLTD.NS | G7: 0
A8: INFY | B8: Infosys | C8: Information Technology | D8: IT | E8: 0.035 | F8: INFY.NS | G8: 0
A9: TCS | B9: TCS | C9: Information Technology | D9: IT | E9: 0.035 | F9: TCS.NS | G9: 0
A10: HCLTECH | B10: HCL Tech | C10: Information Technology | D10: IT | E10: 0.015 | F10: HCLTECH.NS | G10: 0
A11: NTPC | B11: NTPC | C11: Power | D11: Thermal Power generation | E11: 0.0325 | F11: NTPC.NS | G11: 0
A12: TATAPOWER | B12: Tata Power | C12: Power | D12: T&D, Generation - diversified | E12: 0.0325 | F12: TATAPOWER.NS | G12: 0
A13: IEX | B13: IEX | C13: Power | D13: Power Exchange | E13: 0.005 | F13: IEX.NS | G13: 0
A14: LODHA | B14: Lodha Developers | C14: Realty | D14: Retail & Commercial developer | E14: 0.02 | F14: LODHA.NS | G14: 0
A15: KRT | B15: REITs (Knowledge Realty Trust) | C15: Realty | D15: REIT | E15: 0.02 | G15: 1
A16: WEWORK | B16: Wework India | C16: Services | D16: Workplace Services | E16: 0.01 | F16: WEWORK.NS | G16: 0
A17: ADANIPORTS | B17: Adani Ports | C17: Services | D17: Ports | E17: 0.03 | F17: ADANIPORTS.NS | G17: 0
A18: WAAREEENER | B18: Waaree Energies | C18: Capital Goods | D18: Solar manufacturing | E18: 0.04 | F18: WAAREEENER.NS | G18: 0
A19: LEMONTREE | B19: Lemontree Hotels | C19: Consumer Services | D19: Hotels | E19: 0.025 | F19: LEMONTREE.NS | G19: 0
A20: INDHOTEL | B20: Indian Hotels | C20: Consumer Services | D20: Hotels | E20: 0.03 | F20: INDHOTEL.NS | G20: 0
A21: ETERNAL | B21: Eternal (Zomato) | C21: Consumer Services | D21: Q - Commerce | E21: 0.025 | F21: ETERNAL.NS | G21: 0
A22: BHARTIARTL | B22: Bharti Airtel | C22: Telecommunication | D22: Telecom | E22: 0.05 | F22: BHARTIARTL.NS | G22: 0
A23: AXISHEALTH | B23: Axis Nifty Healthcare ETF | C23: Healthcare | D23: Healthcare diversified | E23: 0.07 | G23: 1
A24: TITAN | B24: Titan | C24: Consumer Durables | D24: Jewellery & Watches | E24: 0.03 | F24: TITAN.NS | G24: 0
A25: ITC | B25: ITC Ltd | C25: Fast Moving Consumer Goods | D25: Cigarettes, FMCG & Paper | E25: 0.02 | F25: ITC.NS | G25: 0
A26: FIEMIND | B26: Fiem Industries | C26: Automobile and Auto Components | D26: Auto ancilliary | E26: 0.005 | F26: FIEMIND.NS | G26: 0
A27: FORCEMOT | B27: Force Motors | C27: Automobile and Auto Components | D27: 4W Auto HCV | E27: 0.02 | F27: FORCEMOT.NS | G27: 0
A28: EICHERMOT | B28: Eicher Motors | C28: Automobile and Auto Components | D28: 2W Auto & HCV | E28: 0.025 | F28: EICHERMOT.NS | G28: 0
A29: M&M | B29: Mahindra & Mahindra | C29: Automobile and Auto Components | D29: 4W Auto LCV | E29: 0.025 | F29: M&M.NS | G29: 0
A30: AMBUJACEM | B30: Ambuja Cements | C30: Construction Materials | D30: Cement | E30: 0.02 | F30: AMBUJACEM.NS | G30: 0
A31: LT | B31: Larsen & Toubro | C31: Construction | D31: Construction - Diversified | E31: 0.02 | F31: LT.NS | G31: 0
A32: VEDL | B32: Vedanta Ltd | C32: Metals & Mining | D32: Explortion, Extracting and Processing | E32: 0.02 | F32: VEDL.NS | G32: 0 | H32: Original cost Rs 672.5/share pre-demerger; cost split across Vedanta Ltd and the four demerged entities (336.25 + 4 x 84.0625).
A33: VEDL-AL | B33: Vedanta Aluminium Metal | C33: Metals & Mining | D33: Vedanta demerged entity | E33: 0 | G33: 1 | H33: Demerged entity; share of original Vedanta cost. Group target (2%) sits on Vedanta Ltd line.
A34: VEDL-PWR | B34: Talwandi Sabo Power (Vedanta Power) | C34: Metals & Mining | D34: Vedanta demerged entity | E34: 0 | G34: 1 | H34: Demerged entity; share of original Vedanta cost. Group target (2%) sits on Vedanta Ltd line.
A35: VEDL-OG | B35: Vedanta oil & gas | C35: Metals & Mining | D35: Vedanta demerged entity | E35: 0 | G35: 1 | H35: Demerged entity; share of original Vedanta cost. Group target (2%) sits on Vedanta Ltd line.
A36: VEDL-IS | B36: Vedanta Iron & Steel | C36: Metals & Mining | D36: Vedanta demerged entity | E36: 0 | G36: 1 | H36: Demerged entity; share of original Vedanta cost. Group target (2%) sits on Vedanta Ltd line.
D37: Total target | E37: =SUM(E2:E36) -> 1

Sheet transactions
A1: txn_id | B1: date | C1: ticker | D1: action (BUY/SELL) | E1: qty | F1: price | G1: change_id | H1: note | I1: signed_qty | J1: signed_value
A2: T001 | B2: 46101 | C2: KOTAKBANK | D2: BUY | E2: 1363 | F2: 366.75 | G2: INIT-001 | H2: Initial model portfolio construction (date assumed = inception) | I2: =IF(E2="","",IF(D2="BUY",E2,-E2)) -> 1363 | J2: =IF(E2="","",I2*F2) -> 499880.25
A3: T002 | B3: 46101 | C3: HDFCBANK | D3: BUY | E3: 1025 | F3: 780.45 | G3: INIT-002 | H3: Initial model portfolio construction (date assumed = inception) | I3: =IF(E3="","",IF(D3="BUY",E3,-E3)) -> 1025 | J3: =IF(E3="","",I3*F3) -> 799961.25
A4: T003 | B4: 46101 | C4: SBIN | D4: BUY | E4: 662 | F4: 1058 | G4: INIT-003 | H4: Initial model portfolio construction (date assumed = inception) | I4: =IF(E4="","",IF(D4="BUY",E4,-E4)) -> 662 | J4: =IF(E4="","",I4*F4) -> 700396
A5: T004 | B5: 46101 | C5: MANAPPURAM | D5: BUY | E5: 1929 | F5: 259.25 | G5: INIT-004 | H5: Initial model portfolio construction (date assumed = inception) | I5: =IF(E5="","",IF(D5="BUY",E5,-E5)) -> 1929 | J5: =IF(E5="","",I5*F5) -> 500093.25
A6: T005 | B6: 46101 | C6: SHRIRAMFIN | D6: BUY | E6: 533 | F6: 938.6 | G6: INIT-005 | H6: Initial model portfolio construction (date assumed = inception) | I6: =IF(E6="","",IF(D6="BUY",E6,-E6)) -> 533 | J6: =IF(E6="","",I6*F6) -> 500273.8
A7: T006 | B7: 46101 | C7: RECLTD | D7: BUY | E7: 1210 | F7: 330.5 | G7: INIT-006 | H7: Initial model portfolio construction (date assumed = inception) | I7: =IF(E7="","",IF(D7="BUY",E7,-E7)) -> 1210 | J7: =IF(E7="","",I7*F7) -> 399905
A8: T007 | B8: 46101 | C8: INFY | D8: BUY | E8: 279 | F8: 1255.9 | G8: INIT-007 | H8: Initial model portfolio construction (date assumed = inception) | I8: =IF(E8="","",IF(D8="BUY",E8,-E8)) -> 279 | J8: =IF(E8="","",I8*F8) -> 350396.1
A9: T008 | B9: 46101 | C9: TCS | D9: BUY | E9: 147 | F9: 2390.6 | G9: INIT-008 | H9: Initial model portfolio construction (date assumed = inception) | I9: =IF(E9="","",IF(D9="BUY",E9,-E9)) -> 147 | J9: =IF(E9="","",I9*F9) -> 351418.2
A10: T009 | B10: 46101 | C10: HCLTECH | D10: BUY | E10: 112 | F10: 1333.7 | G10: INIT-009 | H10: Initial model portfolio construction (date assumed = inception) | I10: =IF(E10="","",IF(D10="BUY",E10,-E10)) -> 112 | J10: =IF(E10="","",I10*F10) -> 149374.4
A11: T010 | B11: 46101 | C11: NTPC | D11: BUY | E11: 853 | F11: 380.95 | G11: INIT-010 | H11: Initial model portfolio construction (date assumed = inception) | I11: =IF(E11="","",IF(D11="BUY",E11,-E11)) -> 853 | J11: =IF(E11="","",I11*F11) -> 324950.35
A12: T011 | B12: 46101 | C12: TATAPOWER | D12: BUY | E12: 808 | F12: 402.4 | G12: INIT-011 | H12: Initial model portfolio construction (date assumed = inception) | I12: =IF(E12="","",IF(D12="BUY",E12,-E12)) -> 808 | J12: =IF(E12="","",I12*F12) -> 325139.2
A13: T012 | B13: 46101 | C13: IEX | D13: BUY | E13: 414 | F13: 120.53 | G13: INIT-012 | H13: Initial model portfolio construction (date assumed = inception) | I13: =IF(E13="","",IF(D13="BUY",E13,-E13)) -> 414 | J13: =IF(E13="","",I13*F13) -> 49899.42
... A36: T035 | B36: 46101 | C36: VEDL-IS | D36: BUY | E36: 298 | F36: 84.0625 | G36: INIT-035 | H36: Initial model portfolio construction (date assumed = inception) | I36: =IF(E36="","",IF(D36="BUY",E36,-E36)) -> 298 | J36: =IF(E36="","",I36*F36) -> 25050.625
I37: =IF(E37="","",IF(D37="BUY",E37,-E37)) | J37: =IF(E37="","",I37*F37)
I38: =IF(E38="","",IF(D38="BUY",E38,-E38)) | J38: =IF(E38="","",I38*F38)
I39: =IF(E39="","",IF(D39="BUY",E39,-E39)) | J39: =IF(E39="","",I39*F39)
I40: =IF(E40="","",IF(D40="BUY",E40,-E40)) | J40: =IF(E40="","",I40*F40)
I41: =IF(E41="","",IF(D41="BUY",E41,-E41)) | J41: =IF(E41="","",I41*F41)
I42: =IF(E42="","",IF(D42="BUY",E42,-E42)) | J42: =IF(E42="","",I42*F42)
I43: =IF(E43="","",IF(D43="BUY",E43,-E43)) | J43: =IF(E43="","",I43*F43)
I44: =IF(E44="","",IF(D44="BUY",E44,-E44)) | J44: =IF(E44="","",I44*F44)
I45: =IF(E45="","",IF(D45="BUY",E45,-E45)) | J45: =IF(E45="","",I45*F45)
I46: =IF(E46="","",IF(D46="BUY",E46,-E46)) | J46: =IF(E46="","",I46*F46)
I47: =IF(E47="","",IF(D47="BUY",E47,-E47)) | J47: =IF(E47="","",I47*F47)
I48: =IF(E48="","",IF(D48="BUY",E48,-E48)) | J48: =IF(E48="","",I48*F48)
... I501: =IF(E501="","",IF(D501="BUY",E501,-E501)) | J501: =IF(E501="","",I501*F501)

Sheet prices
A1: date | B1: KOTAKBANK | C1: HDFCBANK | D1: SBIN | E1: MANAPPURAM | F1: SHRIRAMFIN | G1: RECLTD | H1: INFY | I1: TCS | J1: HCLTECH | K1: NTPC | L1: TATAPOWER | M1: IEX | N1: LODHA | O1: KRT | P1: WEWORK | Q1: ADANIPORTS | R1: WAAREEENER | S1: LEMONTREE | T1: INDHOTEL | U1: ETERNAL | V1: BHARTIARTL | W1: AXISHEALTH | X1: TITAN | Y1: ITC | Z1: FIEMIND | AA1: FORCEMOT | AB1: EICHERMOT | AC1: M&M | AD1: AMBUJACEM | AE1: LT | AF1: VEDL | AG1: VEDL-AL | AH1: VEDL-PWR | AI1: VEDL-OG | AJ1: VEDL-IS | AK1: NIFTY500
A2: 46101 | B2: 366.75 | C2: 780.45 | D2: 1058 | E2: 259.25 | F2: 938.6 | G2: 330.5 | H2: 1255.9 | I2: 2390.6 | J2: 1333.7 | K2: 380.95 | L2: 402.4 | M2: 120.53 | N2: 796.9 | O2: 117.1 | P2: 470 | Q2: 1365.4 | R2: 3165.9 | S2: 105.66 | T2: 615.55 | U2: 232.29 | V2: 1846.1 | W2: 146.65 | X2: 4106.6 | Y2: 299.95 | Z2: 2026.8 | AA2: 21585 | AB2: 6909 | AC2: 3066.1 | AD2: 420.55 | AE2: 3434.8 | AF2: 336.25 | AG2: 84.0625 | AH2: 84.0625 | AI2: 84.0625 | AJ2: 84.0625 | AK2: 21327.9
A3: 46310 | B3: 445.55 | C3: 725.15 | D3: 959 | E3: 323.3 | F3: 950.75 | G3: 309.95 | H3: 1109.1 | I3: 2356.7 | J3: 1370.1 | K3: 314.2 | L3: 349.75 | M3: 108.25 | N3: 1054.4 | O3: 116.111 | P3: 664.75 | Q3: 1744.6 | R3: 2493.4 | S3: 113.41 | T3: 745 | U3: 319.6 | V3: 1846.9 | W3: 160.3 | X3: 4439.6 | Y3: 264.3 | Z3: 1825 | AA3: 17604 | AB3: 7237.5 | AC3: 2848.4 | AD3: 349.4 | AE3: 3648.7 | AF3: 245.4 | AG3: 359 | AH3: 32.43 | AI3: 31.5 | AJ3: 29.55 | AK3: 22155.55
A64: Row 2 = inception (stock prices = your avg. cost; Nifty = 21,327.9 from your file). Row 3 = cached prices from your last save on 15-Oct-2026. Add each new update date as a new row below (max 60 rows).

Sheet positions
A1: date | B1: =prices!B1 -> KOTAKBANK | C1: =prices!C1 -> HDFCBANK | D1: =prices!D1 -> SBIN | E1: =prices!E1 -> MANAPPURAM | F1: =prices!F1 -> SHRIRAMFIN | G1: =prices!G1 -> RECLTD | H1: =prices!H1 -> INFY | I1: =prices!I1 -> TCS | ... AJ1: =prices!AJ1 -> VEDL-IS
A2: =IF(prices!A2="","",prices!A2) -> 46101 | B2: =IF($A2="","",SUMIFS(transactions!$I$2:$I$501,transactions!$C$2:$C$501,B$1,transactions!$B$2:$B$501,"<="&$A2)) -> 1363 | C2: =IF($A2="","",SUMIFS(transactions!$I$2:$I$501,transactions!$C$2:$C$501,C$1,transactions!$B$2:$B$501,"<="&$A2)) -> 1025 | D2: =IF($A2="","",SUMIFS(transactions!$I$2:$I$501,transactions!$C$2:$C$501,D$1,transactions!$B$2:$B$501,"<="&$A2)) -> 662 | E2: =IF($A2="","",SUMIFS(transactions!$I$2:$I$501,transactions!$C$2:$C$501,E$1,transactions!$B$2:$B$501,"<="&$A2)) -> 1929 | F2: =IF($A2="","",SUMIFS(transactions!$I$2:$I$501,transactions!$C$2:$C$501,F$1,transactions!$B$2:$B$501,"<="&$A2)) -> 533 | G2: =IF($A2="","",SUMIFS(transactions!$I$2:$I$501,transactions!$C$2:$C$501,G$1,transactions!$B$2:$B$501,"<="&$A2)) -> 1210 | H2: =IF($A2="","",SUMIFS(transactions!$I$2:$I$501,transactions!$C$2:$C$501,H$1,transactions!$B$2:$B$501,"<="&$A2)) -> 279 | I2: =IF($A2="","",SUMIFS(transactions!$I$2:$I$501,transactions!$C$2:$C$501,I$1,transactions!$B$2:$B$501,"<="&$A2)) -> 147 | ... AJ2: =IF($A2="","",SUMIFS(transactions!$I$2:$I$501,transactions!$C$2:$C$501,AJ$1,transactions!$B$2:$B$501,"<="&$A2)) -> 298
A3: =IF(prices!A3="","",prices!A3) -> 46310 | B3: =IF($A3="","",SUMIFS(transactions!$I$2:$I$501,transactions!$C$2:$C$501,B$1,transactions!$B$2:$B$501,"<="&$A3)) -> 1363 | C3: =IF($A3="","",SUMIFS(transactions!$I$2:$I$501,transactions!$C$2:$C$501,C$1,transactions!$B$2:$B$501,"<="&$A3)) -> 1025 | D3: =IF($A3="","",SUMIFS(transactions!$I$2:$I$501,transactions!$C$2:$C$501,D$1,transactions!$B$2:$B$501,"<="&$A3)) -> 662 | E3: =IF($A3="","",SUMIFS(transactions!$I$2:$I$501,transactions!$C$2:$C$501,E$1,transactions!$B$2:$B$501,"<="&$A3)) -> 1929 | F3: =IF($A3="","",SUMIFS(transactions!$I$2:$I$501,transactions!$C$2:$C$501,F$1,transactions!$B$2:$B$501,"<="&$A3)) -> 533 | G3: =IF($A3="","",SUMIFS(transactions!$I$2:$I$501,transactions!$C$2:$C$501,G$1,transactions!$B$2:$B$501,"<="&$A3)) -> 1210 | H3: =IF($A3="","",SUMIFS(transactions!$I$2:$I$501,transactions!$C$2:$C$501,H$1,transactions!$B$2:$B$501,"<="&$A3)) -> 279 | I3: =IF($A3="","",SUMIFS(transactions!$I$2:$I$501,transactions!$C$2:$C$501,I$1,transactions!$B$2:$B$501,"<="&$A3)) -> 147 | ... AJ3: =IF($A3="","",SUMIFS(transactions!$I$2:$I$501,transactions!$C$2:$C$501,AJ$1,transactions!$B$2:$B$501,"<="&$A3)) -> 298
A4: =IF(prices!A4="","",prices!A4) | B4: =IF($A4="","",SUMIFS(transactions!$I$2:$I$501,transactions!$C$2:$C$501,B$1,transactions!$B$2:$B$501,"<="&$A4)) | C4: =IF($A4="","",SUMIFS(transactions!$I$2:$I$501,transactions!$C$2:$C$501,C$1,transactions!$B$2:$B$501,"<="&$A4)) | D4: =IF($A4="","",SUMIFS(transactions!$I$2:$I$501,transactions!$C$2:$C$501,D$1,transactions!$B$2:$B$501,"<="&$A4)) | E4: =IF($A4="","",SUMIFS(transactions!$I$2:$I$501,transactions!$C$2:$C$501,E$1,transactions!$B$2:$B$501,"<="&$A4)) | F4: =IF($A4="","",SUMIFS(transactions!$I$2:$I$501,transactions!$C$2:$C$501,F$1,transactions!$B$2:$B$501,"<="&$A4)) | G4: =IF($A4="","",SUMIFS(transactions!$I$2:$I$501,transactions!$C$2:$C$501,G$1,transactions!$B$2:$B$501,"<="&$A4)) | H4: =IF($A4="","",SUMIFS(transactions!$I$2:$I$501,transactions!$C$2:$C$501,H$1,transactions!$B$2:$B$501,"<="&$A4)) | I4: =IF($A4="","",SUMIFS(transactions!$I$2:$I$501,transactions!$C$2:$C$501,I$1,transactions!$B$2:$B$501,"<="&$A4)) | ... AJ4: =IF($A4="","",SUMIFS(transactions!$I$2:$I$501,transactions!$C$2:$C$501,AJ$1,transactions!$B$2:$B$501,"<="&$A4))
A5: =IF(prices!A5="","",prices!A5) | B5: =IF($A5="","",SUMIFS(transactions!$I$2:$I$501,transactions!$C$2:$C$501,B$1,transactions!$B$2:$B$501,"<="&$A5)) | C5: =IF($A5="","",SUMIFS(transactions!$I$2:$I$501,transactions!$C$2:$C$501,C$1,transactions!$B$2:$B$501,"<="&$A5)) | D5: =IF($A5="","",SUMIFS(transactions!$I$2:$I$501,transactions!$C$2:$C$501,D$1,transactions!$B$2:$B$501,"<="&$A5)) | E5: =IF($A5="","",SUMIFS(transactions!$I$2:$I$501,transactions!$C$2:$C$501,E$1,transactions!$B$2:$B$501,"<="&$A5)) | F5: =IF($A5="","",SUMIFS(transactions!$I$2:$I$501,transactions!$C$2:$C$501,F$1,transactions!$B$2:$B$501,"<="&$A5)) | G5: =IF($A5="","",SUMIFS(transactions!$I$2:$I$501,transactions!$C$2:$C$501,G$1,transactions!$B$2:$B$501,"<="&$A5)) | H5: =IF($A5="","",SUMIFS(transactions!$I$2:$I$501,transactions!$C$2:$C$501,H$1,transactions!$B$2:$B$501,"<="&$A5)) | I5: =IF($A5="","",SUMIFS(transactions!$I$2:$I$501,transactions!$C$2:$C$501,I$1,transactions!$B$2:$B$501,"<="&$A5)) | ... AJ5: =IF($A5="","",SUMIFS(transactions!$I$2:$I$501,transactions!$C$2:$C$501,AJ$1,transactions!$B$2:$B$501,"<="&$A5))
A6: =IF(prices!A6="","",prices!A6) | B6: =IF($A6="","",SUMIFS(transactions!$I$2:$I$501,transactions!$C$2:$C$501,B$1,transactions!$B$2:$B$501,"<="&$A6)) | C6: =IF($A6="","",SUMIFS(transactions!$I$2:$I$501,transactions!$C$2:$C$501,C$1,transactions!$B$2:$B$501,"<="&$A6)) | D6: =IF($A6="","",SUMIFS(transactions!$I$2:$I$501,transactions!$C$2:$C$501,D$1,transactions!$B$2:$B$501,"<="&$A6)) | E6: =IF($A6="","",SUMIFS(transactions!$I$2:$I$501,transactions!$C$2:$C$501,E$1,transactions!$B$2:$B$501,"<="&$A6)) | F6: =IF($A6="","",SUMIFS(transactions!$I$2:$I$501,transactions!$C$2:$C$501,F$1,transactions!$B$2:$B$501,"<="&$A6)) | G6: =IF($A6="","",SUMIFS(transactions!$I$2:$I$501,transactions!$C$2:$C$501,G$1,transactions!$B$2:$B$501,"<="&$A6)) | H6: =IF($A6="","",SUMIFS(transactions!$I$2:$I$501,transactions!$C$2:$C$501,H$1,transactions!$B$2:$B$501,"<="&$A6)) | I6: =IF($A6="","",SUMIFS(transactions!$I$2:$I$501,transactions!$C$2:$C$501,I$1,transactions!$B$2:$B$501,"<="&$A6)) | ... AJ6: =IF($A6="","",SUMIFS(transactions!$I$2:$I$501,transactions!$C$2:$C$501,AJ$1,transactions!$B$2:$B$501,"<="&$A6))
A7: =IF(prices!A7="","",prices!A7) | B7: =IF($A7="","",SUMIFS(transactions!$I$2:$I$501,transactions!$C$2:$C$501,B$1,transactions!$B$2:$B$501,"<="&$A7)) | C7: =IF($A7="","",SUMIFS(transactions!$I$2:$I$501,transactions!$C$2:$C$501,C$1,transactions!$B$2:$B$501,"<="&$A7)) | D7: =IF($A7="","",SUMIFS(transactions!$I$2:$I$501,transactions!$C$2:$C$501,D$1,transactions!$B$2:$B$501,"<="&$A7)) | E7: =IF($A7="","",SUMIFS(transactions!$I$2:$I$501,transactions!$C$2:$C$501,E$1,transactions!$B$2:$B$501,"<="&$A7)) | F7: =IF($A7="","",SUMIFS(transactions!$I$2:$I$501,transactions!$C$2:$C$501,F$1,transactions!$B$2:$B$501,"<="&$A7)) | G7: =IF($A7="","",SUMIFS(transactions!$I$2:$I$501,transactions!$C$2:$C$501,G$1,transactions!$B$2:$B$501,"<="&$A7)) | H7: =IF($A7="","",SUMIFS(transactions!$I$2:$I$501,transactions!$C$2:$C$501,H$1,transactions!$B$2:$B$501,"<="&$A7)) | I7: =IF($A7="","",SUMIFS(transactions!$I$2:$I$501,transactions!$C$2:$C$501,I$1,transactions!$B$2:$B$501,"<="&$A7)) | ... AJ7: =IF($A7="","",SUMIFS(transactions!$I$2:$I$501,transactions!$C$2:$C$501,AJ$1,transactions!$B$2:$B$501,"<="&$A7))
A8: =IF(prices!A8="","",prices!A8) | B8: =IF($A8="","",SUMIFS(transactions!$I$2:$I$501,transactions!$C$2:$C$501,B$1,transactions!$B$2:$B$501,"<="&$A8)) | C8: =IF($A8="","",SUMIFS(transactions!$I$2:$I$501,transactions!$C$2:$C$501,C$1,transactions!$B$2:$B$501,"<="&$A8)) | D8: =IF($A8="","",SUMIFS(transactions!$I$2:$I$501,transactions!$C$2:$C$501,D$1,transactions!$B$2:$B$501,"<="&$A8)) | E8: =IF($A8="","",SUMIFS(transactions!$I$2:$I$501,transactions!$C$2:$C$501,E$1,transactions!$B$2:$B$501,"<="&$A8)) | F8: =IF($A8="","",SUMIFS(transactions!$I$2:$I$501,transactions!$C$2:$C$501,F$1,transactions!$B$2:$B$501,"<="&$A8)) | G8: =IF($A8="","",SUMIFS(transactions!$I$2:$I$501,transactions!$C$2:$C$501,G$1,transactions!$B$2:$B$501,"<="&$A8)) | H8: =IF($A8="","",SUMIFS(transactions!$I$2:$I$501,transactions!$C$2:$C$501,H$1,transactions!$B$2:$B$501,"<="&$A8)) | I8: =IF($A8="","",SUMIFS(transactions!$I$2:$I$501,transactions!$C$2:$C$501,I$1,transactions!$B$2:$B$501,"<="&$A8)) | ... AJ8: =IF($A8="","",SUMIFS(transactions!$I$2:$I$501,transactions!$C$2:$C$501,AJ$1,transactions!$B$2:$B$501,"<="&$A8))
A9: =IF(prices!A9="","",prices!A9) | B9: =IF($A9="","",SUMIFS(transactions!$I$2:$I$501,transactions!$C$2:$C$501,B$1,transactions!$B$2:$B$501,"<="&$A9)) | C9: =IF($A9="","",SUMIFS(transactions!$I$2:$I$501,transactions!$C$2:$C$501,C$1,transactions!$B$2:$B$501,"<="&$A9)) | D9: =IF($A9="","",SUMIFS(transactions!$I$2:$I$501,transactions!$C$2:$C$501,D$1,transactions!$B$2:$B$501,"<="&$A9)) | E9: =IF($A9="","",SUMIFS(transactions!$I$2:$I$501,transactions!$C$2:$C$501,E$1,transactions!$B$2:$B$501,"<="&$A9)) | F9: =IF($A9="","",SUMIFS(transactions!$I$2:$I$501,transactions!$C$2:$C$501,F$1,transactions!$B$2:$B$501,"<="&$A9)) | G9: =IF($A9="","",SUMIFS(transactions!$I$2:$I$501,transactions!$C$2:$C$501,G$1,transactions!$B$2:$B$501,"<="&$A9)) | H9: =IF($A9="","",SUMIFS(transactions!$I$2:$I$501,transactions!$C$2:$C$501,H$1,transactions!$B$2:$B$501,"<="&$A9)) | I9: =IF($A9="","",SUMIFS(transactions!$I$2:$I$501,transactions!$C$2:$C$501,I$1,transactions!$B$2:$B$501,"<="&$A9)) | ... AJ9: =IF($A9="","",SUMIFS(transactions!$I$2:$I$501,transactions!$C$2:$C$501,AJ$1,transactions!$B$2:$B$501,"<="&$A9))
A10: =IF(prices!A10="","",prices!A10) | B10: =IF($A10="","",SUMIFS(transactions!$I$2:$I$501,transactions!$C$2:$C$501,B$1,transactions!$B$2:$B$501,"<="&$A10)) | C10: =IF($A10="","",SUMIFS(transactions!$I$2:$I$501,transactions!$C$2:$C$501,C$1,transactions!$B$2:$B$501,"<="&$A10)) | D10: =IF($A10="","",SUMIFS(transactions!$I$2:$I$501,transactions!$C$2:$C$501,D$1,transactions!$B$2:$B$501,"<="&$A10)) | E10: =IF($A10="","",SUMIFS(transactions!$I$2:$I$501,transactions!$C$2:$C$501,E$1,transactions!$B$2:$B$501,"<="&$A10)) | F10: =IF($A10="","",SUMIFS(transactions!$I$2:$I$501,transactions!$C$2:$C$501,F$1,transactions!$B$2:$B$501,"<="&$A10)) | G10: =IF($A10="","",SUMIFS(transactions!$I$2:$I$501,transactions!$C$2:$C$501,G$1,transactions!$B$2:$B$501,"<="&$A10)) | H10: =IF($A10="","",SUMIFS(transactions!$I$2:$I$501,transactions!$C$2:$C$501,H$1,transactions!$B$2:$B$501,"<="&$A10)) | I10: =IF($A10="","",SUMIFS(transactions!$I$2:$I$501,transactions!$C$2:$C$501,I$1,transactions!$B$2:$B$501,"<="&$A10)) | ... AJ10: =IF($A10="","",SUMIFS(transactions!$I$2:$I$501,transactions!$C$2:$C$501,AJ$1,transactions!$B$2:$B$501,"<="&$A10))
A11: =IF(prices!A11="","",prices!A11) | B11: =IF($A11="","",SUMIFS(transactions!$I$2:$I$501,transactions!$C$2:$C$501,B$1,transactions!$B$2:$B$501,"<="&$A11)) | C11: =IF($A11="","",SUMIFS(transactions!$I$2:$I$501,transactions!$C$2:$C$501,C$1,transactions!$B$2:$B$501,"<="&$A11)) | D11: =IF($A11="","",SUMIFS(transactions!$I$2:$I$501,transactions!$C$2:$C$501,D$1,transactions!$B$2:$B$501,"<="&$A11)) | E11: =IF($A11="","",SUMIFS(transactions!$I$2:$I$501,transactions!$C$2:$C$501,E$1,transactions!$B$2:$B$501,"<="&$A11)) | F11: =IF($A11="","",SUMIFS(transactions!$I$2:$I$501,transactions!$C$2:$C$501,F$1,transactions!$B$2:$B$501,"<="&$A11)) | G11: =IF($A11="","",SUMIFS(transactions!$I$2:$I$501,transactions!$C$2:$C$501,G$1,transactions!$B$2:$B$501,"<="&$A11)) | H11: =IF($A11="","",SUMIFS(transactions!$I$2:$I$501,transactions!$C$2:$C$501,H$1,transactions!$B$2:$B$501,"<="&$A11)) | I11: =IF($A11="","",SUMIFS(transactions!$I$2:$I$501,transactions!$C$2:$C$501,I$1,transactions!$B$2:$B$501,"<="&$A11)) | ... AJ11: =IF($A11="","",SUMIFS(transactions!$I$2:$I$501,transactions!$C$2:$C$501,AJ$1,transactions!$B$2:$B$501,"<="&$A11))
A12: =IF(prices!A12="","",prices!A12) | B12: =IF($A12="","",SUMIFS(transactions!$I$2:$I$501,transactions!$C$2:$C$501,B$1,transactions!$B$2:$B$501,"<="&$A12)) | C12: =IF($A12="","",SUMIFS(transactions!$I$2:$I$501,transactions!$C$2:$C$501,C$1,transactions!$B$2:$B$501,"<="&$A12)) | D12: =IF($A12="","",SUMIFS(transactions!$I$2:$I$501,transactions!$C$2:$C$501,D$1,transactions!$B$2:$B$501,"<="&$A12)) | E12: =IF($A12="","",SUMIFS(transactions!$I$2:$I$501,transactions!$C$2:$C$501,E$1,transactions!$B$2:$B$501,"<="&$A12)) | F12: =IF($A12="","",SUMIFS(transactions!$I$2:$I$501,transactions!$C$2:$C$501,F$1,transactions!$B$2:$B$501,"<="&$A12)) | G12: =IF($A12="","",SUMIFS(transactions!$I$2:$I$501,transactions!$C$2:$C$501,G$1,transactions!$B$2:$B$501,"<="&$A12)) | H12: =IF($A12="","",SUMIFS(transactions!$I$2:$I$501,transactions!$C$2:$C$501,H$1,transactions!$B$2:$B$501,"<="&$A12)) | I12: =IF($A12="","",SUMIFS(transactions!$I$2:$I$501,transactions!$C$2:$C$501,I$1,transactions!$B$2:$B$501,"<="&$A12)) | ... AJ12: =IF($A12="","",SUMIFS(transactions!$I$2:$I$501,transactions!$C$2:$C$501,AJ$1,transactions!$B$2:$B$501,"<="&$A12))
A13: =IF(prices!A13="","",prices!A13) | B13: =IF($A13="","",SUMIFS(transactions!$I$2:$I$501,transactions!$C$2:$C$501,B$1,transactions!$B$2:$B$501,"<="&$A13)) | C13: =IF($A13="","",SUMIFS(transactions!$I$2:$I$501,transactions!$C$2:$C$501,C$1,transactions!$B$2:$B$501,"<="&$A13)) | D13: =IF($A13="","",SUMIFS(transactions!$I$2:$I$501,transactions!$C$2:$C$501,D$1,transactions!$B$2:$B$501,"<="&$A13)) | E13: =IF($A13="","",SUMIFS(transactions!$I$2:$I$501,transactions!$C$2:$C$501,E$1,transactions!$B$2:$B$501,"<="&$A13)) | F13: =IF($A13="","",SUMIFS(transactions!$I$2:$I$501,transactions!$C$2:$C$501,F$1,transactions!$B$2:$B$501,"<="&$A13)) | G13: =IF($A13="","",SUMIFS(transactions!$I$2:$I$501,transactions!$C$2:$C$501,G$1,transactions!$B$2:$B$501,"<="&$A13)) | H13: =IF($A13="","",SUMIFS(transactions!$I$2:$I$501,transactions!$C$2:$C$501,H$1,transactions!$B$2:$B$501,"<="&$A13)) | I13: =IF($A13="","",SUMIFS(transactions!$I$2:$I$501,transactions!$C$2:$C$501,I$1,transactions!$B$2:$B$501,"<="&$A13)) | ... AJ13: =IF($A13="","",SUMIFS(transactions!$I$2:$I$501,transactions!$C$2:$C$501,AJ$1,transactions!$B$2:$B$501,"<="&$A13))
... A61: =IF(prices!A61="","",prices!A61) | B61: =IF($A61="","",SUMIFS(transactions!$I$2:$I$501,transactions!$C$2:$C$501,B$1,transactions!$B$2:$B$501,"<="&$A61)) | C61: =IF($A61="","",SUMIFS(transactions!$I$2:$I$501,transactions!$C$2:$C$501,C$1,transactions!$B$2:$B$501,"<="&$A61)) | D61: =IF($A61="","",SUMIFS(transactions!$I$2:$I$501,transactions!$C$2:$C$501,D$1,transactions!$B$2:$B$501,"<="&$A61)) | E61: =IF($A61="","",SUMIFS(transactions!$I$2:$I$501,transactions!$C$2:$C$501,E$1,transactions!$B$2:$B$501,"<="&$A61)) | F61: =IF($A61="","",SUMIFS(transactions!$I$2:$I$501,transactions!$C$2:$C$501,F$1,transactions!$B$2:$B$501,"<="&$A61)) | G61: =IF($A61="","",SUMIFS(transactions!$I$2:$I$501,transactions!$C$2:$C$501,G$1,transactions!$B$2:$B$501,"<="&$A61)) | H61: =IF($A61="","",SUMIFS(transactions!$I$2:$I$501,transactions!$C$2:$C$501,H$1,transactions!$B$2:$B$501,"<="&$A61)) | I61: =IF($A61="","",SUMIFS(transactions!$I$2:$I$501,transactions!$C$2:$C$501,I$1,transactions!$B$2:$B$501,"<="&$A61)) | ... AJ61: =IF($A61="","",SUMIFS(transactions!$I$2:$I$501,transactions!$C$2:$C$501,AJ$1,transactions!$B$2:$B$501,"<="&$A61))

Sheet nav
A1: date | B1: holdings_value | C1: cash | D1: nav_value | E1: portfolio_index | F1: nifty500_level | G1: benchmark_index | H1: alpha_pp | I1: drawdown
A2: =IF(prices!A2="","",prices!A2) -> 46101 | B2: =IF($A2="","",SUMPRODUCT(positions!B2:AJ2,prices!B2:AJ2)) -> 9995812.2 | C2: =IF($A2="","",settings!$B$3-SUMIFS(transactions!$J$2:$J$501,transactions!$B$2:$B$501,"<="&$A2)) -> 4187.83 | D2: =IF($A2="","",B2+C2) -> 10000000 | E2: =IF($A2="","",D2/settings!$B$3*100) -> 100 | F2: =IF($A2="","",prices!AK2) -> 21327.9 | G2: =IF($A2="","",F2/INDEX($F$2:$F$61,MATCH(settings!$B$2,$A$2:$A$61,0))*100) -> 100 | H2: =IF($A2="","",E2-G2) -> 0 | I2: =IF($A2="","",E2/MAX($E$2:E2)-1) -> 0
A3: =IF(prices!A3="","",prices!A3) -> 46310 | B3: =IF($A3="","",SUMPRODUCT(positions!B3:AJ3,prices!B3:AJ3)) -> 10223272 | C3: =IF($A3="","",settings!$B$3-SUMIFS(transactions!$J$2:$J$501,transactions!$B$2:$B$501,"<="&$A3)) -> 4187.83 | D3: =IF($A3="","",B3+C3) -> 10227460 | E3: =IF($A3="","",D3/settings!$B$3*100) -> 102.2746 | F3: =IF($A3="","",prices!AK3) -> 22155.55 | G3: =IF($A3="","",F3/INDEX($F$2:$F$61,MATCH(settings!$B$2,$A$2:$A$61,0))*100) -> 103.8806 | H3: =IF($A3="","",E3-G3) -> -1.6059995 | I3: =IF($A3="","",E3/MAX($E$2:E3)-1) -> 0
A4: =IF(prices!A4="","",prices!A4) | B4: =IF($A4="","",SUMPRODUCT(positions!B4:AJ4,prices!B4:AJ4)) | C4: =IF($A4="","",settings!$B$3-SUMIFS(transactions!$J$2:$J$501,transactions!$B$2:$B$501,"<="&$A4)) | D4: =IF($A4="","",B4+C4) | E4: =IF($A4="","",D4/settings!$B$3*100) | F4: =IF($A4="","",prices!AK4) | G4: =IF($A4="","",F4/INDEX($F$2:$F$61,MATCH(settings!$B$2,$A$2:$A$61,0))*100) | H4: =IF($A4="","",E4-G4) | I4: =IF($A4="","",E4/MAX($E$2:E4)-1)
A5: =IF(prices!A5="","",prices!A5) | B5: =IF($A5="","",SUMPRODUCT(positions!B5:AJ5,prices!B5:AJ5)) | C5: =IF($A5="","",settings!$B$3-SUMIFS(transactions!$J$2:$J$501,transactions!$B$2:$B$501,"<="&$A5)) | D5: =IF($A5="","",B5+C5) | E5: =IF($A5="","",D5/settings!$B$3*100) | F5: =IF($A5="","",prices!AK5) | G5: =IF($A5="","",F5/INDEX($F$2:$F$61,MATCH(settings!$B$2,$A$2:$A$61,0))*100) | H5: =IF($A5="","",E5-G5) | I5: =IF($A5="","",E5/MAX($E$2:E5)-1)
A6: =IF(prices!A6="","",prices!A6) | B6: =IF($A6="","",SUMPRODUCT(positions!B6:AJ6,prices!B6:AJ6)) | C6: =IF($A6="","",settings!$B$3-SUMIFS(transactions!$J$2:$J$501,transactions!$B$2:$B$501,"<="&$A6)) | D6: =IF($A6="","",B6+C6) | E6: =IF($A6="","",D6/settings!$B$3*100) | F6: =IF($A6="","",prices!AK6) | G6: =IF($A6="","",F6/INDEX($F$2:$F$61,MATCH(settings!$B$2,$A$2:$A$61,0))*100) | H6: =IF($A6="","",E6-G6) | I6: =IF($A6="","",E6/MAX($E$2:E6)-1)
A7: =IF(prices!A7="","",prices!A7) | B7: =IF($A7="","",SUMPRODUCT(positions!B7:AJ7,prices!B7:AJ7)) | C7: =IF($A7="","",settings!$B$3-SUMIFS(transactions!$J$2:$J$501,transactions!$B$2:$B$501,"<="&$A7)) | D7: =IF($A7="","",B7+C7) | E7: =IF($A7="","",D7/settings!$B$3*100) | F7: =IF($A7="","",prices!AK7) | G7: =IF($A7="","",F7/INDEX($F$2:$F$61,MATCH(settings!$B$2,$A$2:$A$61,0))*100) | H7: =IF($A7="","",E7-G7) | I7: =IF($A7="","",E7/MAX($E$2:E7)-1)
A8: =IF(prices!A8="","",prices!A8) | B8: =IF($A8="","",SUMPRODUCT(positions!B8:AJ8,prices!B8:AJ8)) | C8: =IF($A8="","",settings!$B$3-SUMIFS(transactions!$J$2:$J$501,transactions!$B$2:$B$501,"<="&$A8)) | D8: =IF($A8="","",B8+C8) | E8: =IF($A8="","",D8/settings!$B$3*100) | F8: =IF($A8="","",prices!AK8) | G8: =IF($A8="","",F8/INDEX($F$2:$F$61,MATCH(settings!$B$2,$A$2:$A$61,0))*100) | H8: =IF($A8="","",E8-G8) | I8: =IF($A8="","",E8/MAX($E$2:E8)-1)
A9: =IF(prices!A9="","",prices!A9) | B9: =IF($A9="","",SUMPRODUCT(positions!B9:AJ9,prices!B9:AJ9)) | C9: =IF($A9="","",settings!$B$3-SUMIFS(transactions!$J$2:$J$501,transactions!$B$2:$B$501,"<="&$A9)) | D9: =IF($A9="","",B9+C9) | E9: =IF($A9="","",D9/settings!$B$3*100) | F9: =IF($A9="","",prices!AK9) | G9: =IF($A9="","",F9/INDEX($F$2:$F$61,MATCH(settings!$B$2,$A$2:$A$61,0))*100) | H9: =IF($A9="","",E9-G9) | I9: =IF($A9="","",E9/MAX($E$2:E9)-1)
A10: =IF(prices!A10="","",prices!A10) | B10: =IF($A10="","",SUMPRODUCT(positions!B10:AJ10,prices!B10:AJ10)) | C10: =IF($A10="","",settings!$B$3-SUMIFS(transactions!$J$2:$J$501,transactions!$B$2:$B$501,"<="&$A10)) | D10: =IF($A10="","",B10+C10) | E10: =IF($A10="","",D10/settings!$B$3*100) | F10: =IF($A10="","",prices!AK10) | G10: =IF($A10="","",F10/INDEX($F$2:$F$61,MATCH(settings!$B$2,$A$2:$A$61,0))*100) | H10: =IF($A10="","",E10-G10) | I10: =IF($A10="","",E10/MAX($E$2:E10)-1)
A11: =IF(prices!A11="","",prices!A11) | B11: =IF($A11="","",SUMPRODUCT(positions!B11:AJ11,prices!B11:AJ11)) | C11: =IF($A11="","",settings!$B$3-SUMIFS(transactions!$J$2:$J$501,transactions!$B$2:$B$501,"<="&$A11)) | D11: =IF($A11="","",B11+C11) | E11: =IF($A11="","",D11/settings!$B$3*100) | F11: =IF($A11="","",prices!AK11) | G11: =IF($A11="","",F11/INDEX($F$2:$F$61,MATCH(settings!$B$2,$A$2:$A$61,0))*100) | H11: =IF($A11="","",E11-G11) | I11: =IF($A11="","",E11/MAX($E$2:E11)-1)
A12: =IF(prices!A12="","",prices!A12) | B12: =IF($A12="","",SUMPRODUCT(positions!B12:AJ12,prices!B12:AJ12)) | C12: =IF($A12="","",settings!$B$3-SUMIFS(transactions!$J$2:$J$501,transactions!$B$2:$B$501,"<="&$A12)) | D12: =IF($A12="","",B12+C12) | E12: =IF($A12="","",D12/settings!$B$3*100) | F12: =IF($A12="","",prices!AK12) | G12: =IF($A12="","",F12/INDEX($F$2:$F$61,MATCH(settings!$B$2,$A$2:$A$61,0))*100) | H12: =IF($A12="","",E12-G12) | I12: =IF($A12="","",E12/MAX($E$2:E12)-1)
A13: =IF(prices!A13="","",prices!A13) | B13: =IF($A13="","",SUMPRODUCT(positions!B13:AJ13,prices!B13:AJ13)) | C13: =IF($A13="","",settings!$B$3-SUMIFS(transactions!$J$2:$J$501,transactions!$B$2:$B$501,"<="&$A13)) | D13: =IF($A13="","",B13+C13) | E13: =IF($A13="","",D13/settings!$B$3*100) | F13: =IF($A13="","",prices!AK13) | G13: =IF($A13="","",F13/INDEX($F$2:$F$61,MATCH(settings!$B$2,$A$2:$A$61,0))*100) | H13: =IF($A13="","",E13-G13) | I13: =IF($A13="","",E13/MAX($E$2:E13)-1)
... A61: =IF(prices!A61="","",prices!A61) | B61: =IF($A61="","",SUMPRODUCT(positions!B61:AJ61,prices!B61:AJ61)) | C61: =IF($A61="","",settings!$B$3-SUMIFS(transactions!$J$2:$J$501,transactions!$B$2:$B$501,"<="&$A61)) | D61: =IF($A61="","",B61+C61) | E61: =IF($A61="","",D61/settings!$B$3*100) | F61: =IF($A61="","",prices!AK61) | G61: =IF($A61="","",F61/INDEX($F$2:$F$61,MATCH(settings!$B$2,$A$2:$A$61,0))*100) | H61: =IF($A61="","",E61-G61) | I61: =IF($A61="","",E61/MAX($E$2:E61)-1)

Sheet calc
A1: CALCULATIONS (formulas only - do not type here)
A2: SUMMARY
A3: As-of date | B3: =MAX(prices!A2:A61) -> 46310 | D3: CHECKS
A4: Inception date | B4: =settings!B2 -> 46101 | D4: Weights incl. cash = 100% | F4: =IF(ABS(M56+M57-1)<0.0001,"OK","CHECK") -> OK
A5: Days since inception | B5: =B3-B4 -> 209 | D5: Target weights = 100% | F5: =IF(ABS(securities!E37-1)<0.0001,"OK","CHECK") -> OK
A6: Starting capital (Rs) | B6: =settings!B3 -> 10000000 | D6: Every ticker has a price | F6: =IF(COUNTIF(I21:I55,0)+SUMPRODUCT(--ISERROR(I21:I55))=0,"OK","CHECK") -> OK
A7: Current NAV (Rs) | B7: =INDEX(nav!D2:D61,MATCH(B3,nav!A2:A61,0)) -> 10227460 | D7: No negative quantities | F7: =IF(COUNTIF(F21:F55,"<0")=0,"OK","CHECK") -> OK
A8: Portfolio return since inception | B8: =B7/B6-1 -> 0.022745982
A9: Nifty 500 at inception | B9: =INDEX(prices!AK2:AK61,MATCH(B4,prices!A2:A61,0)) -> 21327.9
A10: Nifty 500 at as-of date | B10: =INDEX(prices!AK2:AK61,MATCH(B3,prices!A2:A61,0)) -> 22155.55
A11: Benchmark return since inception | B11: =B10/B9-1 -> 0.038805977
A12: Alpha since inception (pp) | B12: =B8-B11 -> -0.016059995
A13: Portfolio annualised (only after 1 yr) | B13: =IF(B5>=365,(1+B8)^(365/B5)-1,"n/a (<1 yr)") -> n/a (<1 yr)
A14: Benchmark annualised (only after 1 yr) | B14: =IF(B5>=365,(1+B11)^(365/B5)-1,"n/a (<1 yr)") -> n/a (<1 yr)
A15: Max drawdown (on recorded dates) | B15: =MIN(nav!I2:I61) -> 0
A16: Cash (Rs) | B16: =INDEX(nav!C2:C61,MATCH(B3,nav!A2:A61,0)) -> 4187.83
A17: Number of positions | B17: =COUNTIF(F21:F55,">0") -> 35
A20: # | B20: Company | C20: Ticker | D20: Sector | E20: Industry | F20: Qty | G20: Avg cost (Rs) | H20: Cost basis (Rs) | I20: Last price (Rs) | J20: Value (Rs) | K20: P&L (Rs) | L20: P&L % | M20: Weight | N20: Target weight | O20: Active weight | P20: Contribution to return
A21: 1 | B21: =securities!B2 -> Kotak Mahindra Bank | C21: =securities!A2 -> KOTAKBANK | D21: =securities!C2 -> Financial Services | E21: =securities!D2 -> Bank - Pvt | F21: =SUMIFS(transactions!$I$2:$I$501,transactions!$C$2:$C$501,C21) -> 1363 | G21: =IFERROR(SUMIFS(transactions!$J$2:$J$501,transactions!$C$2:$C$501,C21,transactions!$D$2:$D$501,"BUY")/SUMIFS(transactions!$I$2:$I$501,transactions!$C$2:$C$501,C21,transactions!$D$2:$D$501,"BUY"),0) -> 366.75 | H21: =F21*G21 -> 499880.25 | I21: =INDEX(prices!$B$2:$AJ$61,MATCH($B$3,prices!$A$2:$A$61,0),MATCH(C21,prices!$B$1:$AJ$1,0)) -> 445.55 | J21: =F21*I21 -> 607284.65 | K21: =J21-H21 -> 107404.4 | L21: =IF(H21=0,0,J21/H21-1) -> 0.21486026 | M21: =J21/$B$7 -> 0.059377857 | N21: =securities!E2 -> 0.05 | O21: =M21-N21 -> 0.0093778573 | P21: =K21/$B$6 -> 0.01074044
A22: 2 | B22: =securities!B3 -> HDFC Bank | C22: =securities!A3 -> HDFCBANK | D22: =securities!C3 -> Financial Services | E22: =securities!D3 -> Bank - Pvt | F22: =SUMIFS(transactions!$I$2:$I$501,transactions!$C$2:$C$501,C22) -> 1025 | G22: =IFERROR(SUMIFS(transactions!$J$2:$J$501,transactions!$C$2:$C$501,C22,transactions!$D$2:$D$501,"BUY")/SUMIFS(transactions!$I$2:$I$501,transactions!$C$2:$C$501,C22,transactions!$D$2:$D$501,"BUY"),0) -> 780.45 | H22: =F22*G22 -> 799961.25 | I22: =INDEX(prices!$B$2:$AJ$61,MATCH($B$3,prices!$A$2:$A$61,0),MATCH(C22,prices!$B$1:$AJ$1,0)) -> 725.15 | J22: =F22*I22 -> 743278.75 | K22: =J22-H22 -> -56682.5 | L22: =IF(H22=0,0,J22/H22-1) -> -0.070856557 | M22: =J22/$B$7 -> 0.072674815 | N22: =securities!E3 -> 0.08 | O22: =M22-N22 -> -0.007325185 | P22: =K22/$B$6 -> -0.00566825
A23: 3 | B23: =securities!B4 -> SBI | C23: =securities!A4 -> SBIN | D23: =securities!C4 -> Financial Services | E23: =securities!D4 -> Bank - PSU | F23: =SUMIFS(transactions!$I$2:$I$501,transactions!$C$2:$C$501,C23) -> 662 | G23: =IFERROR(SUMIFS(transactions!$J$2:$J$501,transactions!$C$2:$C$501,C23,transactions!$D$2:$D$501,"BUY")/SUMIFS(transactions!$I$2:$I$501,transactions!$C$2:$C$501,C23,transactions!$D$2:$D$501,"BUY"),0) -> 1058 | H23: =F23*G23 -> 700396 | I23: =INDEX(prices!$B$2:$AJ$61,MATCH($B$3,prices!$A$2:$A$61,0),MATCH(C23,prices!$B$1:$AJ$1,0)) -> 959 | J23: =F23*I23 -> 634858 | K23: =J23-H23 -> -65538 | L23: =IF(H23=0,0,J23/H23-1) -> -0.093572779 | M23: =J23/$B$7 -> 0.062073869 | N23: =securities!E4 -> 0.07 | O23: =M23-N23 -> -0.0079261311 | P23: =K23/$B$6 -> -0.0065538
A24: 4 | B24: =securities!B5 -> Manappuram Finance | C24: =securities!A5 -> MANAPPURAM | D24: =securities!C5 -> Financial Services | E24: =securities!D5 -> NBFC - Gold & MFI | F24: =SUMIFS(transactions!$I$2:$I$501,transactions!$C$2:$C$501,C24) -> 1929 | G24: =IFERROR(SUMIFS(transactions!$J$2:$J$501,transactions!$C$2:$C$501,C24,transactions!$D$2:$D$501,"BUY")/SUMIFS(transactions!$I$2:$I$501,transactions!$C$2:$C$501,C24,transactions!$D$2:$D$501,"BUY"),0) -> 259.25 | H24: =F24*G24 -> 500093.25 | I24: =INDEX(prices!$B$2:$AJ$61,MATCH($B$3,prices!$A$2:$A$61,0),MATCH(C24,prices!$B$1:$AJ$1,0)) -> 323.3 | J24: =F24*I24 -> 623645.7 | K24: =J24-H24 -> 123552.45 | L24: =IF(H24=0,0,J24/H24-1) -> 0.24705882 | M24: =J24/$B$7 -> 0.060977575 | N24: =securities!E5 -> 0.05 | O24: =M24-N24 -> 0.010977575 | P24: =K24/$B$6 -> 0.012355245
A25: 5 | B25: =securities!B6 -> Shriram Finance | C25: =securities!A6 -> SHRIRAMFIN | D25: =securities!C6 -> Financial Services | E25: =securities!D6 -> NBFC - Auto | F25: =SUMIFS(transactions!$I$2:$I$501,transactions!$C$2:$C$501,C25) -> 533 | G25: =IFERROR(SUMIFS(transactions!$J$2:$J$501,transactions!$C$2:$C$501,C25,transactions!$D$2:$D$501,"BUY")/SUMIFS(transactions!$I$2:$I$501,transactions!$C$2:$C$501,C25,transactions!$D$2:$D$501,"BUY"),0) -> 938.6 | H25: =F25*G25 -> 500273.8 | I25: =INDEX(prices!$B$2:$AJ$61,MATCH($B$3,prices!$A$2:$A$61,0),MATCH(C25,prices!$B$1:$AJ$1,0)) -> 950.75 | J25: =F25*I25 -> 506749.75 | K25: =J25-H25 -> 6475.95 | L25: =IF(H25=0,0,J25/H25-1) -> 0.012944811 | M25: =J25/$B$7 -> 0.049547958 | N25: =securities!E6 -> 0.05 | O25: =M25-N25 -> -0.00045204195 | P25: =K25/$B$6 -> 0.000647595
A26: 6 | B26: =securities!B7 -> REC Ltd | C26: =securities!A7 -> RECLTD | D26: =securities!C7 -> Financial Services | E26: =securities!D7 -> NBFC - Power | F26: =SUMIFS(transactions!$I$2:$I$501,transactions!$C$2:$C$501,C26) -> 1210 | G26: =IFERROR(SUMIFS(transactions!$J$2:$J$501,transactions!$C$2:$C$501,C26,transactions!$D$2:$D$501,"BUY")/SUMIFS(transactions!$I$2:$I$501,transactions!$C$2:$C$501,C26,transactions!$D$2:$D$501,"BUY"),0) -> 330.5 | H26: =F26*G26 -> 399905 | I26: =INDEX(prices!$B$2:$AJ$61,MATCH($B$3,prices!$A$2:$A$61,0),MATCH(C26,prices!$B$1:$AJ$1,0)) -> 309.95 | J26: =F26*I26 -> 375039.5 | K26: =J26-H26 -> -24865.5 | L26: =IF(H26=0,0,J26/H26-1) -> -0.062178517 | M26: =J26/$B$7 -> 0.036669858 | N26: =securities!E7 -> 0.04 | O26: =M26-N26 -> -0.0033301419 | P26: =K26/$B$6 -> -0.00248655
A27: 7 | B27: =securities!B8 -> Infosys | C27: =securities!A8 -> INFY | D27: =securities!C8 -> Information Technology | E27: =securities!D8 -> IT | F27: =SUMIFS(transactions!$I$2:$I$501,transactions!$C$2:$C$501,C27) -> 279 | G27: =IFERROR(SUMIFS(transactions!$J$2:$J$501,transactions!$C$2:$C$501,C27,transactions!$D$2:$D$501,"BUY")/SUMIFS(transactions!$I$2:$I$501,transactions!$C$2:$C$501,C27,transactions!$D$2:$D$501,"BUY"),0) -> 1255.9 | H27: =F27*G27 -> 350396.1 | I27: =INDEX(prices!$B$2:$AJ$61,MATCH($B$3,prices!$A$2:$A$61,0),MATCH(C27,prices!$B$1:$AJ$1,0)) -> 1109.1 | J27: =F27*I27 -> 309438.9 | K27: =J27-H27 -> -40957.2 | L27: =IF(H27=0,0,J27/H27-1) -> -0.11688829 | M27: =J27/$B$7 -> 0.030255695 | N27: =securities!E8 -> 0.035 | O27: =M27-N27 -> -0.0047443055 | P27: =K27/$B$6 -> -0.00409572
A28: 8 | B28: =securities!B9 -> TCS | C28: =securities!A9 -> TCS | D28: =securities!C9 -> Information Technology | E28: =securities!D9 -> IT | F28: =SUMIFS(transactions!$I$2:$I$501,transactions!$C$2:$C$501,C28) -> 147 | G28: =IFERROR(SUMIFS(transactions!$J$2:$J$501,transactions!$C$2:$C$501,C28,transactions!$D$2:$D$501,"BUY")/SUMIFS(transactions!$I$2:$I$501,transactions!$C$2:$C$501,C28,transactions!$D$2:$D$501,"BUY"),0) -> 2390.6 | H28: =F28*G28 -> 351418.2 | I28: =INDEX(prices!$B$2:$AJ$61,MATCH($B$3,prices!$A$2:$A$61,0),MATCH(C28,prices!$B$1:$AJ$1,0)) -> 2356.7 | J28: =F28*I28 -> 346434.9 | K28: =J28-H28 -> -4983.3 | L28: =IF(H28=0,0,J28/H28-1) -> -0.01418054 | M28: =J28/$B$7 -> 0.033873015 | N28: =securities!E9 -> 0.035 | O28: =M28-N28 -> -0.001126985 | P28: =K28/$B$6 -> -0.00049833
A29: 9 | B29: =securities!B10 -> HCL Tech | C29: =securities!A10 -> HCLTECH | D29: =securities!C10 -> Information Technology | E29: =securities!D10 -> IT | F29: =SUMIFS(transactions!$I$2:$I$501,transactions!$C$2:$C$501,C29) -> 112 | G29: =IFERROR(SUMIFS(transactions!$J$2:$J$501,transactions!$C$2:$C$501,C29,transactions!$D$2:$D$501,"BUY")/SUMIFS(transactions!$I$2:$I$501,transactions!$C$2:$C$501,C29,transactions!$D$2:$D$501,"BUY"),0) -> 1333.7 | H29: =F29*G29 -> 149374.4 | I29: =INDEX(prices!$B$2:$AJ$61,MATCH($B$3,prices!$A$2:$A$61,0),MATCH(C29,prices!$B$1:$AJ$1,0)) -> 1370.1 | J29: =F29*I29 -> 153451.2 | K29: =J29-H29 -> 4076.8 | L29: =IF(H29=0,0,J29/H29-1) -> 0.027292495 | M29: =J29/$B$7 -> 0.015003843 | N29: =securities!E10 -> 0.015 | O29: =M29-N29 -> 3.8428633e-06 | P29: =K29/$B$6 -> 0.00040768
A30: 10 | B30: =securities!B11 -> NTPC | C30: =securities!A11 -> NTPC | D30: =securities!C11 -> Power | E30: =securities!D11 -> Thermal Power generation | F30: =SUMIFS(transactions!$I$2:$I$501,transactions!$C$2:$C$501,C30) -> 853 | G30: =IFERROR(SUMIFS(transactions!$J$2:$J$501,transactions!$C$2:$C$501,C30,transactions!$D$2:$D$501,"BUY")/SUMIFS(transactions!$I$2:$I$501,transactions!$C$2:$C$501,C30,transactions!$D$2:$D$501,"BUY"),0) -> 380.95 | H30: =F30*G30 -> 324950.35 | I30: =INDEX(prices!$B$2:$AJ$61,MATCH($B$3,prices!$A$2:$A$61,0),MATCH(C30,prices!$B$1:$AJ$1,0)) -> 314.2 | J30: =F30*I30 -> 268012.6 | K30: =J30-H30 -> -56937.75 | L30: =IF(H30=0,0,J30/H30-1) -> -0.17521985 | M30: =J30/$B$7 -> 0.026205197 | N30: =securities!E11 -> 0.0325 | O30: =M30-N30 -> -0.0062948029 | P30: =K30/$B$6 -> -0.005693775
A31: 11 | B31: =securities!B12 -> Tata Power | C31: =securities!A12 -> TATAPOWER | D31: =securities!C12 -> Power | E31: =securities!D12 -> T&D, Generation - diversified | F31: =SUMIFS(transactions!$I$2:$I$501,transactions!$C$2:$C$501,C31) -> 808 | G31: =IFERROR(SUMIFS(transactions!$J$2:$J$501,transactions!$C$2:$C$501,C31,transactions!$D$2:$D$501,"BUY")/SUMIFS(transactions!$I$2:$I$501,transactions!$C$2:$C$501,C31,transactions!$D$2:$D$501,"BUY"),0) -> 402.4 | H31: =F31*G31 -> 325139.2 | I31: =INDEX(prices!$B$2:$AJ$61,MATCH($B$3,prices!$A$2:$A$61,0),MATCH(C31,prices!$B$1:$AJ$1,0)) -> 349.75 | J31: =F31*I31 -> 282598 | K31: =J31-H31 -> -42541.2 | L31: =IF(H31=0,0,J31/H31-1) -> -0.13083996 | M31: =J31/$B$7 -> 0.027631299 | N31: =securities!E12 -> 0.0325 | O31: =M31-N31 -> -0.004868701 | P31: =K31/$B$6 -> -0.00425412
A32: 12 | B32: =securities!B13 -> IEX | C32: =securities!A13 -> IEX | D32: =securities!C13 -> Power | E32: =securities!D13 -> Power Exchange | F32: =SUMIFS(transactions!$I$2:$I$501,transactions!$C$2:$C$501,C32) -> 414 | G32: =IFERROR(SUMIFS(transactions!$J$2:$J$501,transactions!$C$2:$C$501,C32,transactions!$D$2:$D$501,"BUY")/SUMIFS(transactions!$I$2:$I$501,transactions!$C$2:$C$501,C32,transactions!$D$2:$D$501,"BUY"),0) -> 120.53 | H32: =F32*G32 -> 49899.42 | I32: =INDEX(prices!$B$2:$AJ$61,MATCH($B$3,prices!$A$2:$A$61,0),MATCH(C32,prices!$B$1:$AJ$1,0)) -> 108.25 | J32: =F32*I32 -> 44815.5 | K32: =J32-H32 -> -5083.92 | L32: =IF(H32=0,0,J32/H32-1) -> -0.10188335 | M32: =J32/$B$7 -> 0.0043818798 | N32: =securities!E13 -> 0.005 | O32: =M32-N32 -> -0.00061812016 | P32: =K32/$B$6 -> -0.000508392
... A55: 35 | B55: =securities!B36 -> Vedanta Iron & Steel | C55: =securities!A36 -> VEDL-IS | D55: =securities!C36 -> Metals & Mining | E55: =securities!D36 -> Vedanta demerged entity | F55: =SUMIFS(transactions!$I$2:$I$501,transactions!$C$2:$C$501,C55) -> 298 | G55: =IFERROR(SUMIFS(transactions!$J$2:$J$501,transactions!$C$2:$C$501,C55,transactions!$D$2:$D$501,"BUY")/SUMIFS(transactions!$I$2:$I$501,transactions!$C$2:$C$501,C55,transactions!$D$2:$D$501,"BUY"),0) -> 84.0625 | H55: =F55*G55 -> 25050.625 | I55: =INDEX(prices!$B$2:$AJ$61,MATCH($B$3,prices!$A$2:$A$61,0),MATCH(C55,prices!$B$1:$AJ$1,0)) -> 29.55 | J55: =F55*I55 -> 8805.9 | K55: =J55-H55 -> -16244.725 | L55: =IF(H55=0,0,J55/H55-1) -> -0.64847584 | M55: =J55/$B$7 -> 0.00086100558 | N55: =securities!E36 -> 0 | O55: =M55-N55 -> 0.00086100558 | P55: =K55/$B$6 -> -0.0016244725
B56: TOTAL HOLDINGS | H56: =SUM(H21:H55) -> 9995812.2 | J56: =SUM(J21:J55) -> 10223272 | K56: =SUM(K21:K55) -> 227459.82 | L56: =IF(H56=0,0,J56/H56-1) -> 0.022755511 | M56: =SUM(M21:M55) -> 0.99959053 | N56: =SUM(N21:N55) -> 1 | P56: =SUM(P21:P55) -> 0.022745982
B57: CASH | J57: =B16 -> 4187.83 | M57: =J57/$B$7 -> 0.00040946922
B58: NAV | J58: =J56+J57 -> 10227460 | M58: =M56+M57 -> 1
A60: SECTOR VIEW
A61: Sector | B61: Cost basis (Rs) | C61: Value (Rs) | D61: Sector return | E61: Weight | F61: Target (from stocks) | G61: Active weight | H61: Contribution to return | I61: Target on thesis sheet | J61: Gap vs thesis sheet
A62: Financial Services | B62: =SUMIFS($H$21:$H$55,$D$21:$D$55,A62) -> 3400509.5 | C62: =SUMIFS($J$21:$J$55,$D$21:$D$55,A62) -> 3490856.4 | D62: =IF(B62=0,0,C62/B62-1) -> 0.026568606 | E62: =C62/$B$7 -> 0.34132193 | F62: =SUMIFS($N$21:$N$55,$D$21:$D$55,A62) -> 0.34 | G62: =E62-F62 -> 0.0013219325 | H62: =SUMIFS($P$21:$P$55,$D$21:$D$55,A62) -> 0.00903468 | I62: 0.34 | J62: =IF(I62="","no thesis sheet",F62-I62) -> 0
A63: Information Technology | B63: =SUMIFS($H$21:$H$55,$D$21:$D$55,A63) -> 851188.7 | C63: =SUMIFS($J$21:$J$55,$D$21:$D$55,A63) -> 809325 | D63: =IF(B63=0,0,C63/B63-1) -> -0.049182631 | E63: =C63/$B$7 -> 0.079132552 | F63: =SUMIFS($N$21:$N$55,$D$21:$D$55,A63) -> 0.085 | G63: =E63-F63 -> -0.0058674476 | H63: =SUMIFS($P$21:$P$55,$D$21:$D$55,A63) -> -0.00418637 | I63: 0.09 | J63: =IF(I63="","no thesis sheet",F63-I63) -> -0.005
A64: Power | B64: =SUMIFS($H$21:$H$55,$D$21:$D$55,A64) -> 699988.97 | C64: =SUMIFS($J$21:$J$55,$D$21:$D$55,A64) -> 595426.1 | D64: =IF(B64=0,0,C64/B64-1) -> -0.14937788 | E64: =C64/$B$7 -> 0.058218376 | F64: =SUMIFS($N$21:$N$55,$D$21:$D$55,A64) -> 0.07 | G64: =E64-F64 -> -0.011781624 | H64: =SUMIFS($P$21:$P$55,$D$21:$D$55,A64) -> -0.010456287 | I64: 0.07 | J64: =IF(I64="","no thesis sheet",F64-I64) -> 0
A65: Realty | B65: =SUMIFS($H$21:$H$55,$D$21:$D$55,A65) -> 400028.7 | C65: =SUMIFS($J$21:$J$55,$D$21:$D$55,A65) -> 462971.99 | D65: =IF(B65=0,0,C65/B65-1) -> 0.15734693 | E65: =C65/$B$7 -> 0.045267544 | F65: =SUMIFS($N$21:$N$55,$D$21:$D$55,A65) -> 0.04 | G65: =E65-F65 -> 0.0052675441 | H65: =SUMIFS($P$21:$P$55,$D$21:$D$55,A65) -> 0.0062943288 | I65: 0.06 | J65: =IF(I65="","no thesis sheet",F65-I65) -> -0.02
...

Sheet changes
A1: change_id | B1: date | C1: ticker | D1: action | E1: from_weight_pct | F1: to_weight_pct | G1: rationale
A2: INIT-001 | B2: 46101 | C2: KOTAKBANK | D2: INITIAL BUY | E2: 0 | F2: =ROUND(securities!E2*100,2) -> 5 | G2: Initial model portfolio construction. Sector thesis: Financial Services (see Theses).
A3: INIT-002 | B3: 46101 | C3: HDFCBANK | D3: INITIAL BUY | E3: 0 | F3: =ROUND(securities!E3*100,2) -> 8 | G3: Initial model portfolio construction. Sector thesis: Financial Services (see Theses).
A4: INIT-003 | B4: 46101 | C4: SBIN | D4: INITIAL BUY | E4: 0 | F4: =ROUND(securities!E4*100,2) -> 7 | G4: Initial model portfolio construction. Sector thesis: Financial Services (see Theses).
A5: INIT-004 | B5: 46101 | C5: MANAPPURAM | D5: INITIAL BUY | E5: 0 | F5: =ROUND(securities!E5*100,2) -> 5 | G5: Initial model portfolio construction. Sector thesis: Financial Services (see Theses).
A6: INIT-005 | B6: 46101 | C6: SHRIRAMFIN | D6: INITIAL BUY | E6: 0 | F6: =ROUND(securities!E6*100,2) -> 5 | G6: Initial model portfolio construction. Sector thesis: Financial Services (see Theses).
A7: INIT-006 | B7: 46101 | C7: RECLTD | D7: INITIAL BUY | E7: 0 | F7: =ROUND(securities!E7*100,2) -> 4 | G7: Initial model portfolio construction. Sector thesis: Financial Services (see Theses).
A8: INIT-007 | B8: 46101 | C8: INFY | D8: INITIAL BUY | E8: 0 | F8: =ROUND(securities!E8*100,2) -> 3.5 | G8: Initial model portfolio construction. Sector thesis: Information Technology (see Theses).
A9: INIT-008 | B9: 46101 | C9: TCS | D9: INITIAL BUY | E9: 0 | F9: =ROUND(securities!E9*100,2) -> 3.5 | G9: Initial model portfolio construction. Sector thesis: Information Technology (see Theses).
A10: INIT-009 | B10: 46101 | C10: HCLTECH | D10: INITIAL BUY | E10: 0 | F10: =ROUND(securities!E10*100,2) -> 1.5 | G10: Initial model portfolio construction. Sector thesis: Information Technology (see Theses).
A11: INIT-010 | B11: 46101 | C11: NTPC | D11: INITIAL BUY | E11: 0 | F11: =ROUND(securities!E11*100,2) -> 3.25 | G11: Initial model portfolio construction. Sector thesis: Power (see Theses).
A12: INIT-011 | B12: 46101 | C12: TATAPOWER | D12: INITIAL BUY | E12: 0 | F12: =ROUND(securities!E12*100,2) -> 3.25 | G12: Initial model portfolio construction. Sector thesis: Power (see Theses).
A13: INIT-012 | B13: 46101 | C13: IEX | D13: INITIAL BUY | E13: 0 | F13: =ROUND(securities!E13*100,2) -> 0.5 | G13: Initial model portfolio construction. Sector thesis: Power (see Theses).
... A36: INIT-035 | B36: 46101 | C36: VEDL-IS | D36: INITIAL BUY | E36: 0 | F36: =ROUND(securities!E36*100,2) -> 0 | G36: Initial model portfolio construction. Sector thesis: Metals & Mining (see Theses).

Sheet theses
A1: sector_sheet | B1: sector | C1: thesis_date | D1: section | E1: text
A2: Financial services | B2: Financial services | C2: 46097 | D2: Rationale for Sector weight | E2: Favour of Credit Growth: The RBI's 125bps repo rate reduction through CY2025 marks the most aggressive easing cycle India has seen since the COVID response, bringing the benchmark rate to 5.25%. Simultaneously, the 100bps CRR cut to 3% released approximately ₹2.5 lakh crore of durable liquidity into the banking system, directly expanding the lendable resource base for banks and NBFCs. Moreover, GST 2.0's simplification from a four-tier to a two-tier structure increases effective household disposable income, particularly in the consumption-heavy middle class, directly translating into higher credit absorption capacity. The combination of monetary easing and fiscal rationalisation is boosting credit, and financial intermediaries are the primary beneficiaries.
A3: Financial services | B3: Financial services | C3: 46097 | D3: Rationale for Sector weight | E3: Sub-Themes: Microfinance: the sector endured a sharp asset quality deterioration through FY25 driven by borrower over-leveraging and collection breakdowns, but as of early 2026 PAR metrics are moderating and new disbursements are performing materially better under tighter regulatory guardrails (₹2 lakh borrower cap, three-lender limit). In gold loans: record domestic gold prices have expanded loan eligibility under the 75% LTV cap, driving gold loan AUM up 42% YoY to ₹15.6 trillion — a structural tailwind for Muthoot, Manappuram, and bank-run gold loan portfolios. Vehicle finance: the GST restructuring on automobiles drove a 20% YoY volume surge in late 2025, directly expanding auto loan origination pipelines. Housing finance: 2 years of volume consolidation driven by affordability fatigue is expected to reverse as the 125bps rate cut meaningfully reduces EMI burden on ₹50–80 lakh ticket-size buyers who were the most rate-sensitive. Business loan: India's formalising SME and startup ecosystem continues to structurally drive working capital and business loan demand, particularly in Tier II/III cities with limited institutional credit penetration.
A4: Financial services | B4: Financial services | C4: 46097 | D4: Rationale for Sector weight | E4: Valuations: Large-cap private banks and select NBFCs are trading at valuations of the prior stress cycle (covid), offering a nice entry point with favourable valuation cushion.
A5: Financial services | B5: Financial services | C5: 46097 | D5: Risks (what could go wrong) | E5: El Niño / Monsoon Risk: Multiple meteorological agencies including Skymet, IMD, and WMO are flagging an evolving El Niño with ~60% probability of below-normal monsoon from June 2026 onwards; historically, weak monsoons compress rural incomes, delay agricultural loan repayments, and elevate stress in kisan credit card portfolios and MFI books concentrated in rain-dependent geographies
A6: Financial services | B6: Financial services | C6: 46097 | D6: Risks (what could go wrong) | E6: Inflationary Reversal / Rate Risk: Sustained geopolitical tensions in energy markets could push crude prices higher, spill into domestic CPI via fuel and transport costs, and force a hike in RBI REPO rates, compressing NIMs across the sector
A7: Financial services | B7: Financial services | C7: 46097 | D7: Risks (what could go wrong) | E7: Deposit Stress: Rising SIP inflows — now running at record monthly levels above ~₹25,000 crore — reflect a structural shift in household savings away from bank fixed deposits and into equity mutual funds; this reduces the low-cost, stable deposit base that banks have historically relied upon to fund credit growth, and if the trend accelerates, it could tighten the liability side of bank balance sheets even as loan demand picks up, compressing the credit-deposit ratio and pressuring funding costs.
A8: Financial services | B8: Financial services | C8: 46097 | D8: Target Weight | E8: 34.0%
A9: IT | B9: Information Technology | C9: 46092 | D9: Rationale for Sector weight | E9: IT companies fell due to 'AI will replace humans' narrative. IT sector, hugely dependent on humans to design and develop softaware (write codes), felt business contraction risk with investors lowering the terminal growth rate assumptions. This triggered broad-based selling across IT stocks. I view this as fear-driven selling, because over the long run, IT companies stand to benefit — provided they successfully pivot train people for prompt engineering and Agentic AI innovation.
A10: IT | B10: Information Technology | C10: 46092 | D10: Rationale for Sector weight | E10: AI, no doubt, is going to stay here and disrupt tarditional workflows and tasks. Recalling the 'Dot-com' bubble, technology stays, but the companies boasting about their tech-led product may not. A similar situation may occur with AI. AI capex by big U.S. tech comapnies is now bigger than all countries' military spend(ex. U.S) at $424 bn (~₹40L crs), increasing at 32% CAGR for 6 yrs. To maintain their lead in the AI race, U.S. hyperscalers are deploying significant free cash flows and taking on debt — yet return visibility on these investments remains limited.
A11: IT | B11: Information Technology | C11: 46092 | D11: Rationale for Sector weight | E11: On the flows side, FIIs have net sold $32.7 billion in Indian equities since October 2024, rotating into undervalued emerging markets and AI-theme plays globally. However, when earnings visibility in those bets deteriorates, India could see a reversal of these outflows.
A12: IT | B12: Information Technology | C12: 46092 | D12: Rationale for Sector weight | E12: From a technical standpoint, the IT sector has corrected ~35% over 15 months. Historically, 30–50% drawdowns have been followed by average forward returns exceeding 50%, with a 92% probability of positive returns over a two-year horizon(A DSP MF study). The sector currently sits in oversold territory (14-day RSI below 20) and appears fairly to slightly undervalued on fundamental metrics. Notably, promoter buying has been observed in select IT names — a constructive signal.
A13: IT | B13: Information Technology | C13: 46092 | D13: Risks (what could go wrong) | E13: Indian IT revenues are USD-denominated but costs are INR-denominated. Any INR appreciation would compress margins further.
... A30: Power | B30: Power / Energy | C30: 46094 | D30: Phasing | E30: 1. Buy 50% of the position now. 2. 50% when the Iran war de-escalates and the sector is trading @lower price.
A31: Real Estate | B31: Real Estate | D31: Rationale for Sector weight | E31: The RBI's 125bps repo rate reduction through CY2025 is the most important macro catalyst for Indian real estate. For every 100bps decline in home loan rates, EMI burden on a ₹50 lakh, 20-year mortgage falls by approximately ₹3,000/month. Along with this, GST 2.0 further expands household disposable income, materially improving affordability for mid-income buyers who had been sitting on the sidelines through the high-rate CY2022–24 period.
A32: Real Estate | B32: Real Estate | D32: Rationale for Sector weight | E32: India’s commercial real estate market witnessed broad-based buoyancy across office, retail, data centres and logistics. Office absorption across the top eight cities is estimated to exceed 59 MSF, while warehousing and industrial leasing is expected to cross 50 MSF for the third consecutive year - underscoring the sector’s structural growth story. Retail leasing gained traction across prime high streets and malls, while the residential market continued its shift towards lifestyle upgrades, with strong demand for premium and luxury housing.
A33: Real Estate | B33: Real Estate | D33: Rationale for Sector weight | E33: Nifty Realty index corrected ~40%, and realty stocks are now trading at pre-covid valuations (lower than 5yr median TTM PE). A mix of realty stocks(capital appreciation) and REITs(capital appreciation + huge dividends) make a strong allocation to Realty sector,
A34: Real Estate | B34: Real Estate | D34: Rationale for Sector weight | E34: REITs and Institutional Capital Are Re-Rating the Sector. Indian REITs delivered low-to-mid 30% returns in 2025 versus negative NIFTY Realty and ~10% NIFTY 50. SEBI's January 2026 reclassification of REITs as equity opens up large passive and active fund flows. Institutional investment into real estate is set to exceed USD 7 billion in 2025, with data centres — now tracking 220 MW of 2026 supply — emerging as a mainstream alternative asset class alongside office.
A35: Real Estate | B35: Real Estate | D35: Risks (what could go wrong) | E35: If interest rates increases, then affordability to buy a home decreases, reducing demand and sales.
A36: Real Estate | B36: Real Estate | D36: Risks (what could go wrong) | E36: Demand from NRIs may reduce if new professionals face visa rejections from high earning countries.
A37: Real Estate | B37: Real Estate | D37: Risks (what could go wrong) | E37: Office supply catchup becoming a vacancy risk if IT/GCC demand softens.
A38: Real Estate | B38: Real Estate | D38: Target Weight | E38: 6.0%
